input/message_arc.txt
A j S 99 208
A k B 96 314
R h 147
R k 79
R k 73
A l S 98 220
A m B 95 654
R m 155
R k 150
A n S 99 67
R m 44
A o B 95 102
R h 20
R l 172
A p B 94 74
A q S 101 20
R o 47
R l 48
R j 110
R j 87
R b 37
R o 31
A r S 98 225
R o 24
R m 67
R r 27
R r 78
R r 49
A s B 96 130
R m 81
R r 71
A t S 98 183
R t 55
A u B 90 410
R k 12
R s 10
A v B 95 131
A w S 98 15
R v 45
R t 79
R w 15
R t 49
A x S 96 35
R v 76
A y B 94 57
A z B 97 74
R m 64
A aa B 98 141
R aa 48
A ab S 103 363
R aa 45
R ab 62
R aa 48
R z 74
R v 10
R m 135
R m 85
R s 85
R j 11
R n 67
A ac S 97 32
R u 81
A ad S 97 111
A ae B 94 44
R m 23
A af S 97 45
R ae 44
R y 57
R p 13
R af 45
R ad 63
A ag B 94 39
A ah B 94 93
A ai B 96 153
R ai 55
R ai 98
A aj B 95 119
R ah 93
R ag 7
R ab 56
A ak B 95 79
R ak 79
R aj 49
R aj 70
A al B 98 35
A am S 95 27
R ag 32
R p 44
R u 64
A an B 96 87
A ao S 100 95
A ap B 97 36
A aq B 94 47
R ao 50
A ar S 100 72
R u 84
R ar 72
R ao 36
R an 60
A as S 97 30
R u 65
A at S 93 61
R as 30
R ad 9
A au B 96 122
A av B 100 25
R ab 134
A aw B 101 167
R ab 111
A ax B 99 105
R aw 63
A ay B 106 7
A az S 107 15
A ba S 105 64
A bb S 105 189
A bc S 103 62
R aw 84
R a 20
R ba 39
A bd S 102 66
A be S 104 186
A bf B 93 209
A bg S 99 10
R bd 66
A bh S 102 69
R ax 68
R bh 65
A bi B 103 10
A bj B 100 84
A bk B 105 81
R be 91
A bl B 102 63
A bm S 104 107
A bn S 104 128
R bn 85
R bm 107
R bn 15
R av 6
R bj 28
R bn 28
R be 85
A bo B 104 99
R bo 85
R ba 25
R bb 79
A bp S 107 468
A bq S 107 30
R bq 30
R bp 42
R bb 110
R bp 100
A br B 102 15
A bs B 107 174
R bl 63
R br 15
A bt S 106 83
R bt 83
A bu S 104 30
A bv B 98 35
A bw S 102 57
A bx S 105 27
A by B 102 13
A bz B 104 15
R bv 35
A ca S 102 937
R ca 85
R bw 29
R ca 30
R ca 89
R ca 86
R ca 117
R ca 136
R bx 27
R bu 16
A cb S 98 64
A cc B 97 56
A cd S 99 13
A ce S 102 189
R ce 127
R ca 39
A cf S 99 25
R cf 9
R ce 62
R ca 79
A cg B 99 125
A ch B 96 42
R cg 57
A ci B 100 71
R ca 71
A cj S 99 50
A ck S 101 79
R ca 70
R cg 68
A cl B 98 27
R ci 21
A cm B 99 63
A cn S 99 700
R cn 80
R cn 64
R cn 70
R cn 94
A co B 96 43
R cn 34
R cn 173
R ck 79
R cn 69
R co 43
R au 25
R au 97
R ch 24
R cc 56
R cn 53
R ca 82
A cp S 98 115
A cq B 94 268
A cr S 98 62
R cp 70
R cp 18
R cr 62
R ch 18
A cs S 96 78
R bf 134
A ct S 96 53
R cq 175
R bf 75
R ct 53
R cs 78
A cu B 98 70
R cu 70
A cv S 96 1038
R cv 106
A cw S 92 40
R cv 144
R cq 56
A cx B 96 144
R cv 74
A cy B 92 14
R cv 122
R cv 49
R cv 80
A cz S 94 20
R cv 134
A da S 92 4
A db S 95 106
A dc S 94 90
R dc 56
A dd B 92 28
A de S 100 76
A df B 92 209
A dg B 93 70
R u 70
R u 46
R dg 62
R df 82
R dg 8
R dd 28
R cy 10
R df 24
R cz 20
R dc 34
A dh S 96 70
A di S 96 44
R cv 152
R di 44
R cv 33
R dh 19
A dj S 90 39
A dk B 93 88
R db 94
A dl B 93 24
R dl 24
R dk 88
A dm S 92 45
A dn S 93 169
R dn 41
R dn 98
R dn 30
A do B 93 70
R do 70
A dp S 90 50
A dq B 88 61
R dq 61
A dr B 85 71
A ds S 89 95
A dt B 88 255
R ds 42
R dt 131
R dt 70
A du B 85 67
R dt 54
A dv S 85 88
A dw S 87 21
A dx S 87 68
R dp 31
R du 50
A dy B 85 108
R dy 84
A dz S 88 54
A ea S 85 16
A eb B 88 47
R dx 34
A ec S 92 78
A ed S 85 131
A ee B 85 21
A ef B 79 32
A eg S 77 284
A eh B 74 89
A ei B 75 141
R eh 40
R eg 85
R ei 55
R ei 86
A ej B 71 94
R eh 49
A ek S 73 138
R ej 87
R ek 70
A el S 72 53
R ej 7
A em B 68 80
A en B 70 100
A eo S 72 14
R eo 14
R el 53
R em 66
A ep B 69 118
R en 100
A eq B 70 148
A er B 69 169
A es B 64 41
A et S 72 526
R et 110
R et 240
R ek 68
R eq 94
R er 76
R eq 54
R er 93
R ep 13
A eu S 73 86
A ev B 69 52
R et 73
A ew S 72 73
A ex B 69 318
A ey B 73 8
R et 42
A ez S 75 44
A fa S 71 21
R ev 52
R ep 50
R ex 56
R fa 21
R ex 109
A fb B 72 18
A fc B 73 46
R ex 120
A fd B 70 102
A fe S 70 63
R ew 62
R fd 39
A ff B 73 15
A fg S 68 47
R eu 71
A fh B 72 310
R eg 97
A fi S 71 15
A fj S 76 52
R eg 70
R fh 93
R ex 33
R ep 8
A fk S 74 81
R fk 69
R fh 70
R fh 66
A fl B 69 107
R fh 66
A fm S 67 11
A fn B 67 516
A fo B 69 62
A fp B 71 43
R fo 62
R fl 24
A fq S 70 119
R fn 121
R fl 72
A fr S 76 183
R fq 76
A fs B 72 112
R fj 52
R fr 42
R fs 66
R ez 44
A ft S 73 235
R fn 100
A fu S 72 178
A fv S 70 47
R fv 47
R fn 118
A fw S 71 50
R fu 78
A fx B 71 395
R ft 235
R fx 97
R fx 50
R fx 41
A fy S 79 88
A fz S 73 428
R fz 97
R fz 151
R fz 76
R fx 54
R fx 59
R fu 54
A ga B 69 25
A gb B 68 69
A gc S 73 117
R fx 44
A gd S 67 88
A ge S 71 276
A gf S 70 24
A gg S 71 47
A gh S 70 153
R gf 24
R gh 27
R gh 107
A gi B 68 23
R fz 104
R gc 47
R gb 20
R gi 23
A gj B 67 139
R gj 139
R fn 93
R ge 73
R gg 47
R ge 58
A gk B 65 134
A gl B 68 25
A gm B 64 49
A gn S 70 38
R fn 84
A go B 64 89
R gk 32
A gp S 72 359
R gn 38
R gh 19
A gq B 65 78
R gk 102
R gq 19
A gr S 70 307
A gs S 68 79
R gr 95
R gr 81
R gq 59
A gt B 64 148
R go 89
R es 5
A gu S 66 189
R gu 40
R gt 71
A gv B 64 64
R gu 91
R gm 49
R es 11
R gu 58
R es 25
R gv 46
A gw S 62 99
A gx B 57 74
A gy B 62 7
A gz B 69 57
R gr 97
R ge 136
R gp 44
R gr 34
R gp 112
R gp 153
A ha S 71 312
R ha 98
A hb S 68 58
A hc S 64 94
A hd B 66 213
R hb 55
A he S 67 41
R hd 112
R he 41
A hf B 66 165
R hf 135
A hg S 74 94
A hh S 71 96
A hi B 69 49
A hj S 67 103
R hf 30
R hd 7
R hj 54
A hk B 69 64
R hh 85
R hk 64
A hl S 64 35
A hm B 58 200
A hn B 64 146
A ho B 69 27
R ha 85
R ge 9
R hh 11
R ha 81
R ha 48
A hp B 69 21
A hq S 70 17
A hr S 69 44
R hq 17
A hs B 71 56
R hs 56
A ht B 73 4
A hu B 70 30
R fk 12
R hg 94
A hv S 75 31
R gp 46
A hw S 73 193
A hx B 70 84
R hu 30
R hx 33
R hx 51
R gc 70
R hw 40
A hy S 71 563
A hz B 72 17
R hy 180
R hy 65
R hy 145
R hy 85
R hy 71
R hw 106
A ia S 77 188
A ib B 75 74
A ic S 73 74
R hn 58
R fr 113
R hp 4
A id B 71 166
A ie B 64 291
R id 53
R id 76
R ia 147
R ic 63
R ic 11
A if B 72 105
R if 59
R fy 72
A ig S 72 6
A ih S 77 158
R hv 4
A ii S 75 32
A ij B 73 37
R id 37
R ij 37
A ik B 73 65
R ik 65
A il S 75 172
R ia 41
R ih 1
A im S 74 87
R im 87
A in B 76 34
R il 54
A io B 75 2278
R io 68
R io 74
R io 128
R ih 83
R io 61
R io 89
R io 49
R io 133
R io 41
R io 54
R io 154
R fr 28
R io 83
R io 38
R io 72
R io 81
R ih 48
R io 94
R io 75
R io 72
R io 162
R io 109
R ih 26
R io 59
A ip S 77 459
R ip 65
R io 89
R ip 98
R io 67
A iq S 73 117
A ir S 77 149
R io 103
R ip 113
A is B 79 37
A it B 77 735
A iu S 79 69
A iv B 80 172
A iw B 83 180
A ix S 90 111
A iy B 77 118
A iz B 83 202
R iz 202
R iw 12
R iv 87
R iw 72
R ed 102
A ja S 81 23
R ds 53
R ix 87
A jb B 85 382
A jc S 88 109
R jb 76
A jd S 91 181
R iw 56
R jb 81
R jb 53
R jb 115
A je B 87 39
A jf S 91 105
R ix 24
R jc 68
A jg S 89 41
R dz 54
R jc 28
A jh S 85 34
A ji B 88 52
A jj B 90 24
R jf 99
R ec 42
R jf 6
R jd 115
R jd 66
A jk B 86 160
R jg 17
A jl S 90 179
R jl 97
A jm S 92 42
R jl 82
R ji 39
A jn B 88 159
A jo S 91 55
A jp S 94 27
A jq S 90 78
R jn 101
R jq 78
A jr B 88 248
R jr 140
R dh 51
A js B 89 58
R jr 53
A jt B 92 48
R jk 131
R jn 58
R jr 55
A ju S 92 5
R jo 7
A jv S 91 33
A jw B 93 17
A jx S 91 108
A jy B 91 43
A jz B 90 67
R ec 36
R jm 42
R ju 5
R jz 67
A ka S 93 104
R js 58
A kb S 90 203
A kc S 85 35
A kd B 88 168
R kb 115
R kd 69
A ke S 90 50
A kf B 85 52
R jx 49
R kd 46
A kg S 90 177
A kh S 90 111
R kh 57
R ke 50
R kg 66
R kg 93
A ki S 89 117
R kd 53
R jb 38
A kj S 87 113
R kj 113
R ki 32
A kk S 85 21
A kl S 87 222
R kl 78
R kl 53
A km B 85 63
R kl 61
R kb 74
A kn S 88 561
R kn 73
R kh 54
R kb 12
R kf 41
R km 62
A ko B 85 59
A kp S 88 32
R ko 59
R km 1
R kl 30
A kq S 85 83
A kr S 89 70
R ki 77
A ks B 77 147
R kn 187
A kt S 87 55
R iw 17
A ku S 83 479
A kv S 83 14
R kq 43
A kw S 79 72
R ks 97
R iy 95
A kx S 80 39
R iy 23
R ks 45
R ks 5
R it 88
R it 149
A ky B 77 57
R ky 57
R it 55
R it 112
A kz S 79 226
R it 36
A la S 74 19
R kw 72
R kz 24
A lb S 75 74
R if 40
A lc S 66 110
R hn 53
R ie 35
R lc 88
A ld S 71 80
R ie 57
R ie 74
A le B 68 57
R ie 112
A lf S 68 42
A lg B 61 177
R lg 85
A lh S 68 160
A li S 68 73
R lh 93
A lj S 66 21
R lg 53
A lk S 64 64
R hm 47
A ll B 60 88
A lm B 62 214
R lk 51
A ln S 64 29
R lm 112
A lo S 65 8
A lp S 64 116
R lm 65
R ln 29
R lp 28
R hm 153
R lp 88
A lq B 63 291
R lq 82
R lq 148
R lq 61
R ld 80
R lg 39
A lr S 70 50
R lr 50
